Workbook

Sheet Review Control
A1: 2026-W34 · Landing Review Control · single-confirmation contract | B1: 2026-W34 · Landing Review Control · single-confirmation contract | C1: 2026-W34 · Landing Review Control · single-confirmation contract | D1: 2026-W34 · Landing Review Control · single-confirmation contract | E1: 2026-W34 · Landing Review Control · single-confirmation contract | F1: 2026-W34 · Landing Review Control · single-confirmation contract
A2: 当前中文内容已由聊天中的一次提交进入机器校验，不需要再填写批准状态。蓝色为 publication 35ba13bb… 冻结事实；英文阶段尚未开始，也不会由本文件自动启动、导入或发布。 | B2: 当前中文内容已由聊天中的一次提交进入机器校验，不需要再填写批准状态。蓝色为 publication 35ba13bb… 冻结事实；英文阶段尚未开始，也不会由本文件自动启动、导入或发布。 | C2: 当前中文内容已由聊天中的一次提交进入机器校验，不需要再填写批准状态。蓝色为 publication 35ba13bb… 冻结事实；英文阶段尚未开始，也不会由本文件自动启动、导入或发布。 | D2: 当前中文内容已由聊天中的一次提交进入机器校验，不需要再填写批准状态。蓝色为 publication 35ba13bb… 冻结事实；英文阶段尚未开始，也不会由本文件自动启动、导入或发布。 | E2: 当前中文内容已由聊天中的一次提交进入机器校验，不需要再填写批准状态。蓝色为 publication 35ba13bb… 冻结事实；英文阶段尚未开始，也不会由本文件自动启动、导入或发布。 | F2: 当前中文内容已由聊天中的一次提交进入机器校验，不需要再填写批准状态。蓝色为 publication 35ba13bb… 冻结事实；英文阶段尚未开始，也不会由本文件自动启动、导入或发布。
A4: Format | B4: Week | C4: Review Scope | D4: Chinese Stage | E4: Machine Contract | F4: English Stage
A5: standard | B5: 2026-W34 | C5: 6 events · 48 Top 8 · 17 machine candidates | D5: ONE CHAT SUBMISSION | E5: validate-xlsx · chinese | F5: ONE LATER CHAT ACCEPTANCE
A6: modern | B6: 2026-W34 | C6: 12 events · 96 Top 8 · 11 machine candidates | D6: ONE CHAT SUBMISSION | E6: validate-xlsx · chinese | F6: ONE LATER CHAT ACCEPTANCE
A9: Frozen Baseline & calculated completeness | B9: Frozen Baseline & calculated completeness | C9: Frozen Baseline & calculated completeness | D9: Frozen Baseline & calculated completeness | E9: Frozen Baseline & calculated completeness | F9: Frozen Baseline & calculated completeness
A10: Metric | B10: Result | C10: Meaning
A11: Review ID | B11: 2026-W34@35ba13bbede2 | C11: 本次人工审核对象
A12: Publication SHA | B12: 35ba13bbede2ffac41cb44761ff545538d398e2d | C12: 生产发布基线
A13: Readiness digest | B13: 66ab1d627d99d286dd79a3296618dc118a00b53c1e4e3994a5daa095008f29b8 | C13: 私有 readiness 契约摘要
A14: KEEP top-copy rows | B14: =COUNTIF('Landing Copy'!$A$5:$A$28,"KEEP") -> 8 | C14: Landing Copy 中将保留的中文段落数
A15: KEEP featured decks | B15: =COUNTIF('Featured Decks'!$A$5:$A$32,"KEEP") -> 8 | C15: Featured Decks 中将进入页面的套牌数
A16: Selected features needing Chinese input | B16: =COUNTIFS('Featured Decks'!$A$5:$A$32,"KEEP",'Featured Decks'!$W$5:$W$32,"<>READY") -> 0 | C16: KEEP 行仍缺类别、中文定位或四张代表单卡
A17: Current-week Top 8 rows | B17: =COUNTA('All Top 8'!$J$5:$J$148) -> 144 | C17: All Top 8 中可供追加的精确牌表数
A18: Bilingual names awaiting approval | B18: =COUNTIF('Bilingual Names'!$I$5:$I$331,"<>APPROVED") -> 0 | C18: 当前分类器身份中尚未确认中文名称的数量
A19: Kept top-copy rows missing Chinese | B19: =COUNTIFS('Landing Copy'!$A$5:$A$28,"KEEP",'Landing Copy'!$D$5:$D$28,"") -> 0 | C19: KEEP 顶端文案中中文正文仍为空的数量

Sheet Landing Copy
A1: 2026-W34 · Landing Copy · Chinese review starts here | B1: 2026-W34 · Landing Copy · Chinese review starts here | C1: 2026-W34 · Landing Copy · Chinese review starts here | D1: 2026-W34 · Landing Copy · Chinese review starts here | E1: 2026-W34 · Landing Copy · Chinese review starts here | F1: 2026-W34 · Landing Copy · Chinese review starts here | G1: 2026-W34 · Landing Copy · Chinese review starts here | H1: 2026-W34 · Landing Copy · Chinese review starts here | I1: 2026-W34 · Landing Copy · Chinese review starts here | J1: 2026-W34 · Landing Copy · Chinese review starts here | K1: 2026-W34 · Landing Copy · Chinese review starts here | L1: 2026-W34 · Landing Copy · Chinese review starts here
A2: 只有 KEEP 行进入 Landing 顶端文字。现有中文内容已完整保留；本次机器校验不要求再次批准。需要链接牌表时，把下方精确 deck:xxxxxxxxxxxxxxxxxxxx 标记放在句中。英文列保持空白，直到另行授权英文阶段。 | B2: 只有 KEEP 行进入 Landing 顶端文字。现有中文内容已完整保留；本次机器校验不要求再次批准。需要链接牌表时，把下方精确 deck:xxxxxxxxxxxxxxxxxxxx 标记放在句中。英文列保持空白，直到另行授权英文阶段。 | C2: 只有 KEEP 行进入 Landing 顶端文字。现有中文内容已完整保留；本次机器校验不要求再次批准。需要链接牌表时，把下方精确 deck:xxxxxxxxxxxxxxxxxxxx 标记放在句中。英文列保持空白，直到另行授权英文阶段。 | D2: 只有 KEEP 行进入 Landing 顶端文字。现有中文内容已完整保留；本次机器校验不要求再次批准。需要链接牌表时，把下方精确 deck:xxxxxxxxxxxxxxxxxxxx 标记放在句中。英文列保持空白，直到另行授权英文阶段。 | E2: 只有 KEEP 行进入 Landing 顶端文字。现有中文内容已完整保留；本次机器校验不要求再次批准。需要链接牌表时，把下方精确 deck:xxxxxxxxxxxxxxxxxxxx 标记放在句中。英文列保持空白，直到另行授权英文阶段。 | F2: 只有 KEEP 行进入 Landing 顶端文字。现有中文内容已完整保留；本次机器校验不要求再次批准。需要链接牌表时，把下方精确 deck:xxxxxxxxxxxxxxxxxxxx 标记放在句中。英文列保持空白，直到另行授权英文阶段。 | G2: 只有 KEEP 行进入 Landing 顶端文字。现有中文内容已完整保留；本次机器校验不要求再次批准。需要链接牌表时，把下方精确 deck:xxxxxxxxxxxxxxxxxxxx 标记放在句中。英文列保持空白，直到另行授权英文阶段。 | H2: 只有 KEEP 行进入 Landing 顶端文字。现有中文内容已完整保留；本次机器校验不要求再次批准。需要链接牌表时，把下方精确 deck:xxxxxxxxxxxxxxxxxxxx 标记放在句中。英文列保持空白，直到另行授权英文阶段。 | I2: 只有 KEEP 行进入 Landing 顶端文字。现有中文内容已完整保留；本次机器校验不要求再次批准。需要链接牌表时，把下方精确 deck:xxxxxxxxxxxxxxxxxxxx 标记放在句中。英文列保持空白，直到另行授权英文阶段。 | J2: 只有 KEEP 行进入 Landing 顶端文字。现有中文内容已完整保留；本次机器校验不要求再次批准。需要链接牌表时，把下方精确 deck:xxxxxxxxxxxxxxxxxxxx 标记放在句中。英文列保持空白，直到另行授权英文阶段。 | K2: 只有 KEEP 行进入 Landing 顶端文字。现有中文内容已完整保留；本次机器校验不要求再次批准。需要链接牌表时，把下方精确 deck:xxxxxxxxxxxxxxxxxxxx 标记放在句中。英文列保持空白，直到另行授权英文阶段。 | L2: 只有 KEEP 行进入 Landing 顶端文字。现有中文内容已完整保留；本次机器校验不要求再次批准。需要链接牌表时，把下方精确 deck:xxxxxxxxxxxxxxxxxxxx 标记放在句中。英文列保持空白，直到另行授权英文阶段。
A4: Review Result | B4: Order | C4: Format | D4: Chinese Copy | E4: English Draft | F4: English Final
A5: KEEP | B5: 1 | C5: standard | D5: 本周MO赛事结构调整后，很多赛制能开起来的比赛都大幅减少。标准赛制在有一场Showcase挑战赛（179人）的情况下，依旧比上周少开两场。 | E5: Following this week's changes to the MTGO event schedule, the number of events that actually fired dropped sharply across many formats. Standard still ran two fewer events than last week despite having a 179-player Showcase Challenge. | F5: Following this week's changes to the MTGO event structure, the number of events that actually fired dropped sharply across many formats. Standard still ran two fewer events than last week despite having a 179-player Showcase Challenge.
A6: KEEP | B6: 2 | C6: standard | D6: Showcase最终由纯绿地落席卷：deck:05f753ee26d10025385a。纯绿地落在环境占比的领先优势也越来越大。而席卷Showcase的版本还在尝试更多HOB单卡，主牌的找地带了Elven Passage，备牌还有给保护+践踏的Warg Tactics，以及打控制套牌的Gigantic Big Bear。另外一套带了三张Bejeweled Warg的套牌在普通挑战赛中也拿下一个亚军：deck:865e322a036a77b48ffb。 | E6: Mono-Green Landfall swept the Showcase: deck:05f753ee26d10025385a. Its lead in metagame share also continues to grow. The winning build experimented with more HOB cards, running Elven Passage as its maindeck land tutor, Warg Tactics in the sideboard for protection and trample, and Gigantic Big Bear for control matchups. Another list with three copies of Bejeweled Warg also finished runner-up in a regular Challenge: deck:865e322a036a77b48ffb. | F6: Mono-Green Landfall topped the Showcase: deck:05f753ee26d10025385a. Its lead in metagame share also continues to grow. The winning build experimented with more HOB cards, running Elven Passage as its maindeck fetch land, Warg Tactics in the sideboard for protection and trample, and Gigantic Big Bear for control matchups. Another list with three copies of Bejeweled Warg also finished runner-up in a regular Challenge: deck:865e322a036a77b48ffb.
A7: KEEP | B7: 3 | C7: standard | D7: 其他HOB新牌方面，一直在玩五色人类的burnet7（实际基本上也是只有他一个人玩），本周还在继续尝试新卡，还在Showcase中拿下八强，获得最终MOCS资格赛的资格：deck:ad4b7bcf0a408f28af1c | E7: Among the other new HOB cards, burnet7—who has been playing Five-Color Humans for some time and is effectively its only pilot—continued trying new additions this week, made the Top 8 of the Showcase, and earned a berth in the final MOCS qualifier: deck:ad4b7bcf0a408f28af1c | F7: Among the other new HOB cards, burnet7—who has been playing Five-Color Humans for some time and is effectively its only pilot—continued trying new additions this week, made the Top 8 of the Showcase, and earned a berth in the Showcase Qualifier: deck:ad4b7bcf0a408f28af1c
A8: KEEP | B8: 4 | C8: standard | D8: 一套带了大量新牌的小黑也在普通挑战赛中拿下八强成绩：deck:2093fcbc2b91ed82d42b。主牌满编了Desolation Prowler、Nighthowl Pursuer还有3张Gollum, Riddle Master，备牌还带了Gollum the Abandoned | E8: A Mono-Black Aggro list packed with new cards also made the Top 8 of a regular Challenge: deck:2093fcbc2b91ed82d42b. The maindeck played four copies each of Desolation Prowler and Nighthowl Pursuer, plus three Gollum, Riddle Master, with Gollum the Abandoned in the sideboard. | F8: A Mono-Black Aggro list packed with new cards also made the Top 8 of a regular Challenge: deck:2093fcbc2b91ed82d42b. The maindeck played four copies each of Desolation Prowler and Nighthowl Pursuer, plus three Gollum, Riddle Master, with Gollum the Abandoned in the sideboard.
A9: KEEP | B9: 1 | C9: modern | D9: 本周MO的比赛结构虽然调整，但摩登魅力不减，和上周开起来的普通挑战赛数量持平。不过混战在本周开始有一些慢慢清晰的趋势。艾斯波怨灵的领先优势开始明朗，本周优势明显。另外两套牌阿布赞缓伤和艾斯波云移的八强占比也都能超过10%。传统豪强红白能量则已经开始彻底掉队。 | E9: MTGO's event schedule changed this week, but Modern remained as popular as ever, with the same number of regular Challenges firing as last week. The crowded field is nevertheless beginning to show some clearer trends. Esper Goryo's pulled ahead decisively this week. Abzan Devoted Druid Combo and Esper Blink each also exceeded a 10% share of Top 8s, while former powerhouse Boros Energy has begun to fall well off the pace. | F9: MTGO's event structure changed this week, but Modern remained as popular as ever, with the same number of regular Challenges firing as last week. The crowded field is nevertheless beginning to show some clearer trends. Esper Goryo's pulled ahead decisively this week. Abzan Devoted Druid Combo and Esper Blink each also exceeded a 10% share of Top 8s, while former powerhouse Boros Energy has begun to fall well off the pace.
A10: KEEP | B10: 2 | C10: modern | D10: 不过依旧还有新套牌进入环境，一套使用了HOB的Bilbo和Key to the Side-Door，并加入黑色的Basim的蓝黑伟代本周拿下一个八强：deck:acc94e69d84da4b303d1 | E10: New decks are still entering the metagame. A Dimir Erayo list using HOB's Bilbo and Key to the Side-Door, plus black for Basim, made a Top 8 this week: deck:acc94e69d84da4b303d1 | F10: New decks are still entering the metagame. A Dimir Erayo list using HOB's Bilbo and Key to the Side-Door, plus black for Basim, made a Top 8 this week: deck:acc94e69d84da4b303d1
A11: KEEP | B11: 3 | C11: modern | D11: 混蓝加入Quantum Riddler续航，还有Mana Leak作为许可咒语的洁斯凯炸地套牌本周也有多个高分、八强成绩：deck:78a27b72522b16549da7。蓝色确实让套牌可以应对的局面更丰富，但法术力基础也变得更差。 | E11: A Jeskai Ponza build that splashes blue for Quantum Riddler as card advantage and Mana Leak as permission posted multiple high-score finishes, including a Top 8, this week: deck:78a27b72522b16549da7. Blue gives the deck answers to a wider range of situations, but also makes its mana base worse. | F11: A Jeskai Ponza build that splashes blue for Quantum Riddler as card advantage and Mana Leak as permission posted multiple high-score finishes, including a Top 8, this week: deck:78a27b72522b16549da7. Blue gives the deck answers to a wider range of situations, but also makes its mana base worse.
A12: KEEP | B12: 4 | C12: modern | D12: 传统介刀套牌中，也开始有加入Bilbo的版本出成绩，本周一套满编并带了一张Key to the Side-Door的版本拿下一个八强：deck:29ffa26abbc811f769a1 | E12: Traditional Steel-Cutter shells are also starting to post results with Bilbo. This week, a list with the full four copies plus one Key to the Side-Door made a Top 8: deck:29ffa26abbc811f769a1 | F12: Traditional Steel-Cutter shells are also starting to post results with Bilbo. This week, a list with the full four copies plus one Key to the Side-Door made a Top 8: deck:29ffa26abbc811f769a1
C13: standard
C14: standard
C15: standard
C16: standard
C17: standard
C18: modern
C19: modern
C20: modern
C21: modern
C22: modern
C23: modern
C24: modern
... C28: modern
A31: Machine-candidate deck references available in this sheet | B31: Machine-candidate deck references available in this sheet | C31: Machine-candidate deck references available in this sheet | D31: Machine-candidate deck references available in this sheet | E31: Machine-candidate deck references available in this sheet | F31: Machine-candidate deck references available in this sheet | G31: Machine-candidate deck references available in this sheet | H31: Machine-candidate deck references available in this sheet | I31: Machine-candidate deck references available in this sheet | J31: Machine-candidate deck references available in this sheet | K31: Machine-candidate deck references available in this sheet | L31: Machine-candidate deck references available in this sheet
A32: Role | B32: Feature Week | C32: Format | D32: Chinese Display | E32: English Display | F32: Deck Page | G32: Event | H32: Date | I32: Rank | J32: Deck | K32: Player | L32: Deck Link ID
A33: MACHINE CANDIDATE | B33: 2026-W34 | C33: standard | D33: 铁木尔元素 · flamyblade · 第7名 | E33: Temur Spellementals · flamyblade · Rank 7 | F33: https://jacelber.github.io/mtgo-data/index.html?format=standard&product=mtgo-top8&week=2026-W34&detail=12852807%3A7&lang=zh | G33: Standard Showcase Challenge · 12852807 | H33: 2026-08-22 | I33: 7 | J33: Temur Spellementals | K33: flamyblade | L33: deck:28cfded64b696a0ce850
A34: MACHINE CANDIDATE | B34: 2026-W34 | C34: standard | D34: 纯绿地落 · FunkiMunki · 第1名 | E34: Mono-Green Landfall · FunkiMunki · Rank 1 | F34: https://jacelber.github.io/mtgo-data/index.html?format=standard&product=mtgo-top8&week=2026-W34&detail=12852807%3A1&lang=zh | G34: Standard Showcase Challenge · 12852807 | H34: 2026-08-22 | I34: 1 | J34: Mono-Green Landfall | K34: FunkiMunki | L34: deck:05f753ee26d10025385a
A35: MACHINE CANDIDATE | B35: 2026-W34 | C35: standard | D35: 蓝黑中速 · claudioh · 第1名 | E35: Dimir Midrange · claudioh · Rank 1 | F35: https://jacelber.github.io/mtgo-data/index.html?format=standard&product=mtgo-top8&week=2026-W34&detail=12852728%3A1&lang=zh | G35: Standard Challenge 32 · 12852728 | H35: 2026-08-21 | I35: 1 | J35: Dimir Midrange | K35: claudioh | L35: deck:a9da3e694cbccedf118d
A36: MACHINE CANDIDATE | B36: 2026-W34 | C36: standard | D36: 红蓝元素 · jakobpablo · 第2名 | E36: Izzet Spellementals · jakobpablo · Rank 2 | F36: https://jacelber.github.io/mtgo-data/index.html?format=standard&product=mtgo-top8&week=2026-W34&detail=12852807%3A2&lang=zh | G36: Standard Showcase Challenge · 12852807 | H36: 2026-08-22 | I36: 2 | J36: Izzet Spellementals | K36: jakobpablo | L36: deck:48044739d220c45fa38f
A37: MACHINE CANDIDATE | B37: 2026-W34 | C37: standard | D37: 蓝白模模 · TrueHero · 第3名 | E37: Azorius Momo · TrueHero · Rank 3 | F37: https://jacelber.github.io/mtgo-data/index.html?format=standard&product=mtgo-top8&week=2026-W34&detail=12851725%3A3&lang=zh | G37: Standard Challenge 32 · 12851725 | H37: 2026-08-18 | I37: 3 | J37: Azorius Momo | K37: TrueHero | L37: deck:f50184abb2fbe29f8b61
A38: MACHINE CANDIDATE | B38: 2026-W34 | C38: standard | D38: 纯绿地落 · JV_7777 · 第1名 | E38: Mono-Green Landfall · JV_7777 · Rank 1 | F38: https://jacelber.github.io/mtgo-data/index.html?format=standard&product=mtgo-top8&week=2026-W34&detail=12852733%3A1&lang=zh | G38: Standard Challenge 32 · 12852733 | H38: 2026-08-21 | I38: 1 | J38: Mono-Green Landfall | K38: JV_7777 | L38: deck:6ac5d33832775b5fa809
A39: MACHINE CANDIDATE | B39: 2026-W34 | C39: standard | D39: 纯绿地落 · dawido · 第1名 | E39: Mono-Green Landfall · dawido · Rank 1 | F39: https://jacelber.github.io/mtgo-data/index.html?format=standard&product=mtgo-top8&week=2026-W34&detail=12852720%3A1&lang=zh | G39: Standard Challenge 16 · 12852720 | H39: 2026-08-20 | I39: 1 | J39: Mono-Green Landfall | K39: dawido | L39: deck:796a8605fb290a66c130
A40: MACHINE CANDIDATE | B40: 2026-W34 | C40: standard | D40: 纯绿地落 · ThePixelNomadX · 第2名 | E40: Mono-Green Landfall · ThePixelNomadX · Rank 2 | F40: https://jacelber.github.io/mtgo-data/index.html?format=standard&product=mtgo-top8&week=2026-W34&detail=12852733%3A2&lang=zh | G40: Standard Challenge 32 · 12852733 | H40: 2026-08-21 | I40: 2 | J40: Mono-Green Landfall | K40: ThePixelNomadX | L40: deck:865e322a036a77b48ffb
A41: MACHINE CANDIDATE | B41: 2026-W34 | C41: standard | D41: 五色人类 · burnet7 · 第5名 | E41: Five-Color Humans · burnet7 · Rank 5 | F41: https://jacelber.github.io/mtgo-data/index.html?format=standard&product=mtgo-top8&week=2026-W34&detail=12852807%3A5&lang=zh | G41: Standard Showcase Challenge · 12852807 | H41: 2026-08-22 | I41: 5 | J41: Five-Color Humans | K41: burnet7 | L41: deck:ad4b7bcf0a408f28af1c
A42: MACHINE CANDIDATE | B42: 2026-W34 | C42: standard | D42: 纯黑快攻 · Bertram · 第6名 | E42: Mono-Black Aggro · Bertram · Rank 6 | F42: https://jacelber.github.io/mtgo-data/index.html?format=standard&product=mtgo-top8&week=2026-W34&detail=12851725%3A6&lang=zh | G42: Standard Challenge 32 · 12851725 | H42: 2026-08-18 | I42: 6 | J42: Mono-Black Aggro | K42: Bertram | L42: deck:2093fcbc2b91ed82d42b
A43: MACHINE CANDIDATE | B43: 2026-W34 | C43: standard | D43: 纯红快攻 · Arkany1 · 第7名 | E43: Mono-Red Aggro · Arkany1 · Rank 7 | F43: https://jacelber.github.io/mtgo-data/index.html?format=standard&product=mtgo-top8&week=2026-W34&detail=12851725%3A7&lang=zh | G43: Standard Challenge 32 · 12851725 | H43: 2026-08-18 | I43: 7 | J43: Mono-Red Aggro | K43: Arkany1 | L43: deck:637e9fc345578cd3181a
A44: MACHINE CANDIDATE | B44: 2026-W34 | C44: standard | D44: 白绿地落 · joaoclaudioms · 第8名 | E44: Selesnya Landfall · joaoclaudioms · Rank 8 | F44: https://jacelber.github.io/mtgo-data/index.html?format=standard&product=mtgo-top8&week=2026-W34&detail=12852807%3A8&lang=zh | G44: Standard Showcase Challenge · 12852807 | H44: 2026-08-22 | I44: 8 | J44: Selesnya Landfall | K44: joaoclaudioms | L44: deck:9e4997f4c6c8be5c7113
... A60: MACHINE CANDIDATE | B60: 2026-W34 | C60: modern | D60: 蓝黑节奏 · bless_von · 第7名 | E60: Dimir Tempo · bless_von · Rank 7 | F60: https://jacelber.github.io/mtgo-data/index.html?format=modern&product=mtgo-top8&week=2026-W34&detail=12851707%3A7&lang=zh | G60: Modern Challenge 32 · 12851707 | H60: 2026-08-19 | I60: 7 | J60: Dimir Tempo | K60: bless_von | L60: deck:abe2d125ef7868d8da39

Sheet Featured Decks
A1: 2026-W34 · Featured Decks · 28 machine candidates | B1: 2026-W34 · Featured Decks · 28 machine candidates | C1: 2026-W34 · Featured Decks · 28 machine candidates | D1: 2026-W34 · Featured Decks · 28 machine candidates | E1: 2026-W34 · Featured Decks · 28 machine candidates | F1: 2026-W34 · Featured Decks · 28 machine candidates | G1: 2026-W34 · Featured Decks · 28 machine candidates | H1: 2026-W34 · Featured Decks · 28 machine candidates | I1: 2026-W34 · Featured Decks · 28 machine candidates | J1: 2026-W34 · Featured Decks · 28 machine candidates | K1: 2026-W34 · Featured Decks · 28 machine candidates | L1: 2026-W34 · Featured Decks · 28 machine candidates | M1: 2026-W34 · Featured Decks · 28 machine candidates | N1: 2026-W34 · Featured Decks · 28 machine candidates | O1: 2026-W34 · Featured Decks · 28 machine candidates | P1: 2026-W34 · Featured Decks · 28 machine candidates | Q1: 2026-W34 · Featured Decks · 28 machine candidates | R1: 2026-W34 · Featured Decks · 28 machine candidates | S1: 2026-W34 · Featured Decks · 28 machine candidates | T1: 2026-W34 · Featured Decks · 28 machine candidates | U1: 2026-W34 · Featured Decks · 28 machine candidates | V1: 2026-W34 · Featured Decks · 28 machine candidates | W1: 2026-W34 · Featured Decks · 28 machine candidates | X1: 2026-W34 · Featured Decks · 28 machine candidates | Y1: 2026-W34 · Featured Decks · 28 machine candidates | Z1: 2026-W34 · Featured Decks · 28 machine candidates | AA1: 2026-W34 · Featured Decks · 28 machine candidates
A2: 机器候选没有主推项。现有 Selection、Category、中文定位与四张代表单卡均完整保留；机器将直接校验这些实质内容，不要求额外批准。英文列保持空白，直到另行授权英文阶段。 | B2: 机器候选没有主推项。现有 Selection、Category、中文定位与四张代表单卡均完整保留；机器将直接校验这些实质内容，不要求额外批准。英文列保持空白，直到另行授权英文阶段。 | C2: 机器候选没有主推项。现有 Selection、Category、中文定位与四张代表单卡均完整保留；机器将直接校验这些实质内容，不要求额外批准。英文列保持空白，直到另行授权英文阶段。 | D2: 机器候选没有主推项。现有 Selection、Category、中文定位与四张代表单卡均完整保留；机器将直接校验这些实质内容，不要求额外批准。英文列保持空白，直到另行授权英文阶段。 | E2: 机器候选没有主推项。现有 Selection、Category、中文定位与四张代表单卡均完整保留；机器将直接校验这些实质内容，不要求额外批准。英文列保持空白，直到另行授权英文阶段。 | F2: 机器候选没有主推项。现有 Selection、Category、中文定位与四张代表单卡均完整保留；机器将直接校验这些实质内容，不要求额外批准。英文列保持空白，直到另行授权英文阶段。 | G2: 机器候选没有主推项。现有 Selection、Category、中文定位与四张代表单卡均完整保留；机器将直接校验这些实质内容，不要求额外批准。英文列保持空白，直到另行授权英文阶段。 | H2: 机器候选没有主推项。现有 Selection、Category、中文定位与四张代表单卡均完整保留；机器将直接校验这些实质内容，不要求额外批准。英文列保持空白，直到另行授权英文阶段。 | I2: 机器候选没有主推项。现有 Selection、Category、中文定位与四张代表单卡均完整保留；机器将直接校验这些实质内容，不要求额外批准。英文列保持空白，直到另行授权英文阶段。 | J2: 机器候选没有主推项。现有 Selection、Category、中文定位与四张代表单卡均完整保留；机器将直接校验这些实质内容，不要求额外批准。英文列保持空白，直到另行授权英文阶段。 | K2: 机器候选没有主推项。现有 Selection、Category、中文定位与四张代表单卡均完整保留；机器将直接校验这些实质内容，不要求额外批准。英文列保持空白，直到另行授权英文阶段。 | L2: 机器候选没有主推项。现有 Selection、Category、中文定位与四张代表单卡均完整保留；机器将直接校验这些实质内容，不要求额外批准。英文列保持空白，直到另行授权英文阶段。 | M2: 机器候选没有主推项。现有 Selection、Category、中文定位与四张代表单卡均完整保留；机器将直接校验这些实质内容，不要求额外批准。英文列保持空白，直到另行授权英文阶段。 | N2: 机器候选没有主推项。现有 Selection、Category、中文定位与四张代表单卡均完整保留；机器将直接校验这些实质内容，不要求额外批准。英文列保持空白，直到另行授权英文阶段。 | O2: 机器候选没有主推项。现有 Selection、Category、中文定位与四张代表单卡均完整保留；机器将直接校验这些实质内容，不要求额外批准。英文列保持空白，直到另行授权英文阶段。 | P2: 机器候选没有主推项。现有 Selection、Category、中文定位与四张代表单卡均完整保留；机器将直接校验这些实质内容，不要求额外批准。英文列保持空白，直到另行授权英文阶段。 | Q2: 机器候选没有主推项。现有 Selection、Category、中文定位与四张代表单卡均完整保留；机器将直接校验这些实质内容，不要求额外批准。英文列保持空白，直到另行授权英文阶段。 | R2: 机器候选没有主推项。现有 Selection、Category、中文定位与四张代表单卡均完整保留；机器将直接校验这些实质内容，不要求额外批准。英文列保持空白，直到另行授权英文阶段。 | S2: 机器候选没有主推项。现有 Selection、Category、中文定位与四张代表单卡均完整保留；机器将直接校验这些实质内容，不要求额外批准。英文列保持空白，直到另行授权英文阶段。 | T2: 机器候选没有主推项。现有 Selection、Category、中文定位与四张代表单卡均完整保留；机器将直接校验这些实质内容，不要求额外批准。英文列保持空白，直到另行授权英文阶段。 | U2: 机器候选没有主推项。现有 Selection、Category、中文定位与四张代表单卡均完整保留；机器将直接校验这些实质内容，不要求额外批准。英文列保持空白，直到另行授权英文阶段。 | V2: 机器候选没有主推项。现有 Selection、Category、中文定位与四张代表单卡均完整保留；机器将直接校验这些实质内容，不要求额外批准。英文列保持空白，直到另行授权英文阶段。 | W2: 机器候选没有主推项。现有 Selection、Category、中文定位与四张代表单卡均完整保留；机器将直接校验这些实质内容，不要求额外批准。英文列保持空白，直到另行授权英文阶段。 | X2: 机器候选没有主推项。现有 Selection、Category、中文定位与四张代表单卡均完整保留；机器将直接校验这些实质内容，不要求额外批准。英文列保持空白，直到另行授权英文阶段。 | Y2: 机器候选没有主推项。现有 Selection、Category、中文定位与四张代表单卡均完整保留；机器将直接校验这些实质内容，不要求额外批准。英文列保持空白，直到另行授权英文阶段。 | Z2: 机器候选没有主推项。现有 Selection、Category、中文定位与四张代表单卡均完整保留；机器将直接校验这些实质内容，不要求额外批准。英文列保持空白，直到另行授权英文阶段。 | AA2: 机器候选没有主推项。现有 Selection、Category、中文定位与四张代表单卡均完整保留；机器将直接校验这些实质内容，不要求额外批准。英文列保持空白，直到另行授权英文阶段。
A4: Selection | B4: Feature Week | C4: Format | D4: Category | E4: Event | F4: Date | G4: Rank | H4: Deck Name EN | I4: Deck Name ZH | J4: Name Status | K4: Player | L4: Deck Link ID | M4: Machine Reasons | N4: Chinese Positioning | O4: Featured Card 1 | P4: Featured Card 2 | Q4: Featured Card 3 | R4: Featured Card 4 | S4: English Draft | T4: English Final | U4: Main Deck | V4: Sideboard | W4: Chinese / Input Check | X4: English Check | Y4: Parent ID | Z4: Subtype ID | AA4: Identity Key
A5: KEEP | B5: 2026-W34 | C5: standard | D5: new_deck | E5: Standard Showcase Challenge · 12852807 | F5: 2026-08-22 | G5: 7 | H5: Temur Spellementals | I5: 铁木尔元素 | J5: APPROVED | K5: flamyblade | L5: deck:28cfded64b696a0ce850 | M5: 新 Archetype | N5: 相比纯元素套牌更倾向于控制，不过还是保留了黯潮蟹+驱群妖的配合，进绿带的分析花粉一定程度上后期也可以导生物。不过个人感觉进绿为了各种单张单卡收益可能不是特别大。 | O5: Eddymurk Crab | P5: Analyze the Pollen | Q5: Prismari Charm | R5: Sunderflock | S5: Compared with common Spellementals builds, this list leans more controlling while retaining the Eddymurk Crab + Sunderflock package. Splashing green for Analyze the Pollen also gives it access to a creature tutor in the late game. Personally, though, I am not convinced the green splash adds enough value through its assortment of one-ofs. | T5: Compared with common Spellementals builds, this list leans more controlling while retaining the Eddymurk Crab + Sunderflock package. Splashing green for Analyze the Pollen also gives it access to a creature tutor in the late game. Personally, though, I am not convinced the green splash adds enough value through its assortment of one-ofs. | U5: 2 × Analyze the Pollen; 2 × Breeding Pool; 1 × Broadside Barrage; 3 × Burst Lightning; 4 × Eddymurk Crab; 1 × Esper Origins; 4 × Flow State; 1 × Forest; 2 × Get Out; 2 × Great Hall of the Biblioplex; 2 × Ill-Timed Explosion; 2 × Impractical Joke; 3 × Island; 1 × Lumbering Worldwagon; 1 × Mountain; 2 × North Wind Avatar; 3 × Opt; 3 × Prismari Charm; 2 × Riverpyre Verge; 3 × Sleight of Hand; 1 × Spell Pierce; 1 × Spell Snare; 4 × Steam Vents; 1 × Stomping Ground; 2 × Sunderflock; 1 × Thornspire Verge; 1 × Traumatic Critique; 4 × Willowrush Verge; 1 × Wistfulness | V5: 1 × Cease/Desist; 1 × Fire Magic; 1 × Ghost Vacuum; 1 × Ill-Timed Explosion; 1 × Pick Your Poison; 1 × Pyroclasm; 1 × Return the Favor; 1 × Sear; 1 × Spectral Interference; 1 × Spell Pierce; 1 × Spell Snare; 1 × The Dawning Archaic; 1 × Wan Shi Tong, Librarian; 1 × Wild Ride; 1 × Wistfulness | W5: =IF(A5<>"KEEP","NOT SELECTED",IF(OR(D5="",N5="",COUNTA(O5:R5)<>4),"NEEDS INPUT",IF(OR(COUNTIF(O5:R5,O5)>1,COUNTIF(O5:R5,P5)>1,COUNTIF(O5:R5,Q5)>1,COUNTIF(O5:R5,R5)>1),"DUPLICATE CARDS",IF(OR(ISERROR(SEARCH("× "&O5&";",U5&"; "&V5&";")),ISERROR(SEARCH("× "&P5&";",U5&"; "&V5&";")),ISERROR(SEARCH("× "&Q5&";",U5&"; "&V5&";")),ISERROR(SEARCH("× "&R5&";",U5&"; "&V5&";"))),"CARD NOT IN DECK","READY")))) -> READY | X5: =IF(A5<>"KEEP","NOT SELECTED",IF(T5="","WAIT FOR ENGLISH STAGE","READY")) -> READY | Y5: temur-spellementals | AA5: standard|temur-spellementals|none
A6: KEEP | B6: 2026-W34 | C6: standard | D6: new_technology | E6: Standard Showcase Challenge · 12852807 | F6: 2026-08-22 | G6: 1 | H6: Mono-Green Landfall | I6: 纯绿地落 | J6: APPROVED | K6: FunkiMunki | L6: deck:05f753ee26d10025385a | M6: 高胜占比 12.8% → 25.0%（+12.23pp）；HOB 新卡：Elven Passage（主2/备0）、Gigantic Big Bear（主0/备1）、Warg Tactics（主0/备2） | N6: 席卷Showcase的版本。尝试了更多HOB单卡，主牌的找地带了Elven Passage，备牌还有给保护+践踏的Warg Tactics，以及打控制套牌的Gigantic Big Bear。 | O6: Elven Passage | P6: Warg Tactics | Q6: Gigantic Big Bear | R6: Earthbender Ascension | S6: The Showcase-winning build. It tried more HOB cards, with Elven Passage as the maindeck fetch land, Warg Tactics in the sideboard for protection and trample, and Gigantic Big Bear for control matchups. | T6: The Showcase-winning build. It tried more HOB cards, with Elven Passage as the maindeck fetch land, Warg Tactics in the sideboard for protection and trample, and Gigantic Big Bear for control matchups. | U6: 3 × Ba Sing Se; 1 × Demolition Field; 4 × Earthbender Ascension; 2 × Elven Passage; 2 × Escape Tunnel; 3 × Esper Origins; 4 × Fabled Passage; 14 × Forest; 3 × Glimpse the Core; 4 × Icetill Explorer; 4 × Llanowar Elves; 1 × Lumbering Worldwagon; 1 × Meltstrider's Resolve; 4 × Mightform Harmonizer; 1 × Promising Vein; 4 × Sapling Nursery; 4 × Sazh's Chocobo; 1 × Surrak, Elusive Hunter | V6: 1 × Gigantic Big Bear; 1 × Keen-Eyed Curator; 1 × Leatherhead, Swamp Stalker; 3 × Meltstrider's Resolve; 4 × Mossborn Hydra; 1 × Surrak, Elusive Hunter; 2 × Torpor Orb; 2 × Warg Tactics | W6: =IF(A6<>"KEEP","NOT SELECTED",IF(OR(D6="",N6="",COUNTA(O6:R6)<>4),"NEEDS INPUT",IF(OR(COUNTIF(O6:R6,O6)>1,COUNTIF(O6:R6,P6)>1,COUNTIF(O6:R6,Q6)>1,COUNTIF(O6:R6,R6)>1),"DUPLICATE CARDS",IF(OR(ISERROR(SEARCH("× "&O6&";",U6&"; "&V6&";")),ISERROR(SEARCH("× "&P6&";",U6&"; "&V6&";")),ISERROR(SEARCH("× "&Q6&";",U6&"; "&V6&";")),ISERROR(SEARCH("× "&R6&";",U6&"; "&V6&";"))),"CARD NOT IN DECK","READY")))) -> READY | X6: =IF(A6<>"KEEP","NOT SELECTED",IF(T6="","WAIT FOR ENGLISH STAGE","READY")) -> READY | Y6: mono-green-landfall | AA6: standard|mono-green-landfall|none
A7: DROP | B7: 2026-W34 | C7: standard | D7: new_technology | E7: Standard Challenge 32 · 12852728 | F7: 2026-08-21 | G7: 1 | H7: Dimir Midrange | I7: 蓝黑中速 | J7: APPROVED | K7: claudioh | L7: deck:a9da3e694cbccedf118d | M7: 高胜占比 3.8% → 14.3%（+10.49pp） | U7: 2 × Bitter Triumph; 4 × Dream Beavers; 3 × Enduring Curiosity; 4 × Floodpits Drowner; 4 × Gloomlake Verge; 3 × Hidden Lair; 4 × Island; 4 × Kaito, Bane of Nightmares; 4 × Requiting Hex; 2 × Restless Reef; 2 × Shoot the Sheriff; 2 × Soulstone Sanctuary; 1 × Spell Pierce; 1 × Spell Snare; 4 × Spyglass Siren; 4 × Swamp; 2 × The Wondrous Wasp; 2 × Tishana's Tidebinder; 2 × Wan Shi Tong, Librarian; 4 × Watery Grave; 2 × We Say Thee Nay! | V7: 2 × Annul; 4 × Duress; 2 × Flashfreeze; 1 × Qarsi Revenant; 2 × Raven Eagle; 1 × Spell Snare; 3 × Strategic Betrayal | W7: =IF(A7<>"KEEP","NOT SELECTED",IF(OR(D7="",N7="",COUNTA(O7:R7)<>4),"NEEDS INPUT",IF(OR(COUNTIF(O7:R7,O7)>1,COUNTIF(O7:R7,P7)>1,COUNTIF(O7:R7,Q7)>1,COUNTIF(O7:R7,R7)>1),"DUPLICATE CARDS",IF(OR(ISERROR(SEARCH("× "&O7&";",U7&"; "&V7&";")),ISERROR(SEARCH("× "&P7&";",U7&"; "&V7&";")),ISERROR(SEARCH("× "&Q7&";",U7&"; "&V7&";")),ISERROR(SEARCH("× "&R7&";",U7&"; "&V7&";"))),"CARD NOT IN DECK","READY")))) -> NOT SELECTED | X7: =IF(A7<>"KEEP","NOT SELECTED",IF(T7="","WAIT FOR ENGLISH STAGE","READY")) -> NOT SELECTED | Y7: dimir-midrange | AA7: standard|dimir-midrange|none
A8: DROP | B8: 2026-W34 | C8: standard | D8: new_technology | E8: Standard Showcase Challenge · 12852807 | F8: 2026-08-22 | G8: 2 | H8: Izzet Spellementals | I8: 红蓝元素 | J8: APPROVED | K8: jakobpablo | L8: deck:48044739d220c45fa38f | M8: 高胜占比 6.8% → 12.1%（+5.36pp） | U8: 3 × Burst Lightning; 4 × Eddymurk Crab; 2 × Get Out; 4 × Hearth Elemental; 2 × Impractical Joke; 6 × Island; 1 × Multiversal Passage; 4 × Opt; 4 × Prismari Charm; 4 × Riverpyre Verge; 4 × Sleight of Hand; 2 × Spell Pierce; 1 × Spell Snare; 4 × Spirebluff Canal; 4 × Steam Vents; 1 × Stormcarved Coast; 4 × Sunderflock; 3 × Traumatic Critique; 3 × Winternight Stories | V8: 2 × Annul; 4 × Colorstorm Stallion; 1 × Flashfreeze; 2 × Hydro-Man, Fluid Felon; 1 × Ral, Crackling Wit; 1 × Sear; 2 × Shore Up; 2 × Spell Snare | W8: =IF(A8<>"KEEP","NOT SELECTED",IF(OR(D8="",N8="",COUNTA(O8:R8)<>4),"NEEDS INPUT",IF(OR(COUNTIF(O8:R8,O8)>1,COUNTIF(O8:R8,P8)>1,COUNTIF(O8:R8,Q8)>1,COUNTIF(O8:R8,R8)>1),"DUPLICATE CARDS",IF(OR(ISERROR(SEARCH("× "&O8&";",U8&"; "&V8&";")),ISERROR(SEARCH("× "&P8&";",U8&"; "&V8&";")),ISERROR(SEARCH("× "&Q8&";",U8&"; "&V8&";")),ISERROR(SEARCH("× "&R8&";",U8&"; "&V8&";"))),"CARD NOT IN DECK","READY")))) -> NOT SELECTED | X8: =IF(A8<>"KEEP","NOT SELECTED",IF(T8="","WAIT FOR ENGLISH STAGE","READY")) -> NOT SELECTED | Y8: izzet-spellementals | AA8: standard|izzet-spellementals|none
A9: DROP | B9: 2026-W34 | C9: standard | D9: new_technology | E9: Standard Challenge 32 · 12851725 | F9: 2026-08-18 | G9: 3 | H9: Azorius Momo | I9: 蓝白模模 | J9: APPROVED | K9: TrueHero | L9: deck:f50184abb2fbe29f8b61 | M9: 环境回归；当前高胜占比 4.3% | U9: 2 × Abandoned Air Temple; 4 × Daydream; 4 × Floodfarm Verge; 4 × Hallowed Fountain; 4 × Momo, Friendly Flier; 2 × Monica Rambeau; 4 × Multiversal Passage; 1 × Nurturing Pixie; 5 × Plains; 4 × Practiced Offense; 4 × Quantum Riddler; 4 × Sage of the Skies; 2 × Seam Rip; 4 × Springleaf Drum; 4 × Starfield Shepherd; 2 × Starting Town; 4 × Steamcore Scholar; 2 × We Say Thee Nay! | V9: 2 × Authority of the Consuls; 2 × Disdainful Stroke; 2 × Erode; 2 × Flashfreeze; 2 × Morningtide's Light; 3 × Rest in Peace; 2 × Spider-Sense | W9: =IF(A9<>"KEEP","NOT SELECTED",IF(OR(D9="",N9="",COUNTA(O9:R9)<>4),"NEEDS INPUT",IF(OR(COUNTIF(O9:R9,O9)>1,COUNTIF(O9:R9,P9)>1,COUNTIF(O9:R9,Q9)>1,COUNTIF(O9:R9,R9)>1),"DUPLICATE CARDS",IF(OR(ISERROR(SEARCH("× "&O9&";",U9&"; "&V9&";")),ISERROR(SEARCH("× "&P9&";",U9&"; "&V9&";")),ISERROR(SEARCH("× "&Q9&";",U9&"; "&V9&";")),ISERROR(SEARCH("× "&R9&";",U9&"; "&V9&";"))),"CARD NOT IN DECK","READY")))) -> NOT SELECTED | X9: =IF(A9<>"KEEP","NOT SELECTED",IF(T9="","WAIT FOR ENGLISH STAGE","READY")) -> NOT SELECTED | Y9: azorius-momo | AA9: standard|azorius-momo|none
A10: DROP | B10: 2026-W34 | C10: standard | D10: new_technology | E10: Standard Challenge 32 · 12852733 | F10: 2026-08-21 | G10: 1 | H10: Mono-Green Landfall | I10: 纯绿地落 | J10: APPROVED | K10: JV_7777 | L10: deck:6ac5d33832775b5fa809 | M10: HOB 新卡：Warg Tactics（主0/备2） | U10: 3 × Ba Sing Se; 1 × Demolition Field; 4 × Earthbender Ascension; 4 × Escape Tunnel; 4 × Esper Origins; 4 × Fabled Passage; 14 × Forest; 4 × Icetill Explorer; 1 × Keen-Eyed Curator; 4 × Llanowar Elves; 1 × Lumbering Worldwagon; 2 × Meltstrider's Resolve; 4 × Mightform Harmonizer; 1 × Royal Treatment; 2 × Sapling Nursery; 4 × Sazh's Chocobo; 2 × Shared Roots; 1 × Surrak, Elusive Hunter | V10: 1 × Keen-Eyed Curator; 2 × Meltstrider's Resolve; 4 × Mossborn Hydra; 1 × Royal Treatment; 2 × Sapling Nursery; 1 × Surrak, Elusive Hunter; 2 × Torpor Orb; 2 × Warg Tactics | W10: =IF(A10<>"KEEP","NOT SELECTED",IF(OR(D10="",N10="",COUNTA(O10:R10)<>4),"NEEDS INPUT",IF(OR(COUNTIF(O10:R10,O10)>1,COUNTIF(O10:R10,P10)>1,COUNTIF(O10:R10,Q10)>1,COUNTIF(O10:R10,R10)>1),"DUPLICATE CARDS",IF(OR(ISERROR(SEARCH("× "&O10&";",U10&"; "&V10&";")),ISERROR(SEARCH("× "&P10&";",U10&"; "&V10&";")),ISERROR(SEARCH("× "&Q10&";",U10&"; "&V10&";")),ISERROR(SEARCH("× "&R10&";",U10&"; "&V10&";"))),"CARD NOT IN DECK","READY")))) -> NOT SELECTED | X10: =IF(A10<>"KEEP","NOT SELECTED",IF(T10="","WAIT FOR ENGLISH STAGE","READY")) -> NOT SELECTED | Y10: mono-green-landfall | AA10: standard|mono-green-landfall|none
A11: DROP | B11: 2026-W34 | C11: standard | D11: new_technology | E11: Standard Challenge 16 · 12852720 | F11: 2026-08-20 | G11: 1 | H11: Mono-Green Landfall | I11: 纯绿地落 | J11: APPROVED | K11: dawido | L11: deck:796a8605fb290a66c130 | M11: HOB 新卡：Gigantic Big Bear（主0/备2）、Warg Tactics（主0/备1） | U11: 3 × Ba Sing Se; 1 × Demolition Field; 4 × Earthbender Ascension; 4 × Escape Tunnel; 4 × Esper Origins; 4 × Fabled Passage; 14 × Forest; 4 × Icetill Explorer; 1 × Keen-Eyed Curator; 4 × Llanowar Elves; 1 × Lumbering Worldwagon; 2 × Meltstrider's Resolve; 4 × Mightform Harmonizer; 1 × Royal Treatment; 2 × Sapling Nursery; 4 × Sazh's Chocobo; 2 × Shared Roots; 1 × Surrak, Elusive Hunter | V11: 2 × Gigantic Big Bear; 1 × Keen-Eyed Curator; 2 × Meltstrider's Resolve; 4 × Mossborn Hydra; 1 × Royal Treatment; 1 × Sapling Nursery; 1 × Surrak, Elusive Hunter; 2 × Torpor Orb; 1 × Warg Tactics | W11: =IF(A11<>"KEEP","NOT SELECTED",IF(OR(D11="",N11="",COUNTA(O11:R11)<>4),"NEEDS INPUT",IF(OR(COUNTIF(O11:R11,O11)>1,COUNTIF(O11:R11,P11)>1,COUNTIF(O11:R11,Q11)>1,COUNTIF(O11:R11,R11)>1),"DUPLICATE CARDS",IF(OR(ISERROR(SEARCH("× "&O11&";",U11&"; "&V11&";")),ISERROR(SEARCH("× "&P11&";",U11&"; "&V11&";")),ISERROR(SEARCH("× "&Q11&";",U11&"; "&V11&";")),ISERROR(SEARCH("× "&R11&";",U11&"; "&V11&";"))),"CARD NOT IN DECK","READY")))) -> NOT SELECTED | X11: =IF(A11<>"KEEP","NOT SELECTED",IF(T11="","WAIT FOR ENGLISH STAGE","READY")) -> NOT SELECTED | Y11: mono-green-landfall | AA11: standard|mono-green-landfall|none
A12: KEEP | B12: 2026-W34 | C12: standard | D12: new_technology | E12: Standard Challenge 32 · 12852733 | F12: 2026-08-21 | G12: 2 | H12: Mono-Green Landfall | I12: 纯绿地落 | J12: APPROVED | K12: ThePixelNomadX | L12: deck:865e322a036a77b48ffb | M12: HOB 新卡：Bejeweled Warg（主3/备0） | N12: 这套带了3张Bejeweled Warg的纯绿地落也拿下一个亚军， | O12: Bejeweled Warg | P12: Earthbender Ascension | Q12: Icetill Explorer | R12: Mightform Harmonizer | S12: This Mono-Green Landfall list with three copies of Bejeweled Warg also finished runner-up. | T12: This Mono-Green Landfall list with three copies of Bejeweled Warg also finished runner-up. | U12: 3 × Archdruid's Charm; 4 × Ba Sing Se; 3 × Bejeweled Warg; 4 × Earthbender Ascension; 4 × Escape Tunnel; 3 × Esper Origins; 4 × Fabled Passage; 13 × Forest; 4 × Icetill Explorer; 1 × Keen-Eyed Curator; 4 × Llanowar Elves; 2 × Lumbering Worldwagon; 4 × Mightform Harmonizer; 2 × Sapling Nursery; 4 × Sazh's Chocobo; 1 × Surrak, Elusive Hunter | V12: 4 × Meltstrider's Resolve; 3 × Mossborn Hydra; 2 × Pawpatch Formation; 2 × Royal Treatment; 2 × Sapling Nursery; 2 × Torpor Orb | W12: =IF(A12<>"KEEP","NOT SELECTED",IF(OR(D12="",N12="",COUNTA(O12:R12)<>4),"NEEDS INPUT",IF(OR(COUNTIF(O12:R12,O12)>1,COUNTIF(O12:R12,P12)>1,COUNTIF(O12:R12,Q12)>1,COUNTIF(O12:R12,R12)>1),"DUPLICATE CARDS",IF(OR(ISERROR(SEARCH("× "&O12&";",U12&"; "&V12&";")),ISERROR(SEARCH("× "&P12&";",U12&"; "&V12&";")),ISERROR(SEARCH("× "&Q12&";",U12&"; "&V12&";")),ISERROR(SEARCH("× "&R12&";",U12&"; "&V12&";"))),"CARD NOT IN DECK","READY")))) -> READY | X12: =IF(A12<>"KEEP","NOT SELECTED",IF(T12="","WAIT FOR ENGLISH STAGE","READY")) -> READY | Y12: mono-green-landfall | AA12: standard|mono-green-landfall|none
A13: KEEP | B13: 2026-W34 | C13: standard | D13: new_technology | E13: Standard Showcase Challenge · 12852807 | F13: 2026-08-22 | G13: 5 | H13: Five-Color Humans | I13: 五色人类 | J13: APPROVED | K13: burnet7 | L13: deck:ad4b7bcf0a408f28af1c | M13: HOB 新卡：Bilbo's Gambit（主0/备1）、Key to the Side-Door（主2/备0）、The Queen of Dale（主2/备0）；构筑变化；deviation=25 | N13: 一直在玩这套牌的burnet7（实际基本上也是只有他一个人玩），本周还在继续尝试新卡，还在Showcase中拿下八强，获得最终MOCS资格赛的资格。 | O13: The Queen of Dale | P13: Key to the Side-Door | Q13: Bilbo's Gambit | R13: Aang, Swift Savior | S13: burnet7 has been piloting this deck for some time (and is effectively its only pilot). They continued testing new cards this week, made the Top 8 of the Showcase, and earned a berth in the final MOCS qualifier. | T13: burnet7 has been piloting this deck for some time (and is effectively its only pilot). They continued testing new cards this week, made the Top 8 of the Showcase, and earned a berth in the final MOCS qualifier. | U13: 3 × Aang, Swift Savior; 3 × Arachne, Psionic Weaver; 1 × Captain America, Super-Soldier; 4 × Cavern of Souls; 4 × Cecil, Dark Knight; 2 × Celestial Reunion; 2 × Cloak and Dagger, Entwined; 1 × Elektra, Daughter of the Hand; 1 × Forest; 2 × Godless Shrine; 2 × Hallowed Fountain; 1 × Honest Rutstein; 2 × Jennifer Walters; 2 × Key to the Side-Door; 1 × King T'Challa; 1 × Lightning, Army of One; 1 × Miles Morales; 1 × Oroku Saki, Shredder Rising; 2 × Overgrown Tomb; 1 × Plains; 4 × Secluded Courtyard; 2 × Serah Farron; 2 × Spectacular Spider-Man; 4 × Starting Town; 1 × Super-Adaptoid; 3 × Temple Garden; 2 × The Queen of Dale; 3 × The Wondrous Wasp; 2 × Zack Fair | V13: 1 × Bilbo's Gambit; 1 × Chomping Changeling; 2 × Mai, Scornful Striker; 2 × Punishing Punch; 2 × Rest in Peace; 1 × Sephiroth, Planet's Heir; 1 × Sheltered by Ghosts; 1 × The Sentry, Golden Guardian; 2 × Torpor Orb; 2 × Winnowing | W13: =IF(A13<>"KEEP","NOT SELECTED",IF(OR(D13="",N13="",COUNTA(O13:R13)<>4),"NEEDS INPUT",IF(OR(COUNTIF(O13:R13,O13)>1,COUNTIF(O13:R13,P13)>1,COUNTIF(O13:R13,Q13)>1,COUNTIF(O13:R13,R13)>1),"DUPLICATE CARDS",IF(OR(ISERROR(SEARCH("× "&O13&";",U13&"; "&V13&";")),ISERROR(SEARCH("× "&P13&";",U13&"; "&V13&";")),ISERROR(SEARCH("× "&Q13&";",U13&"; "&V13&";")),ISERROR(SEARCH("× "&R13&";",U13&"; "&V13&";"))),"CARD NOT IN DECK","READY")))) -> READY | X13: =IF(A13<>"KEEP","NOT SELECTED",IF(T13="","WAIT FOR ENGLISH STAGE","READY")) -> READY | Y13: five-color-humans | AA13: standard|five-color-humans|none
A14: KEEP | B14: 2026-W34 | C14: standard | D14: new_technology | E14: Standard Challenge 32 · 12851725 | F14: 2026-08-18 | G14: 6 | H14: Mono-Black Aggro | I14: 纯黑快攻 | J14: APPROVED | K14: Bertram | L14: deck:2093fcbc2b91ed82d42b | M14: HOB 新卡：Desolation Prowler（主4/备0）、Gollum the Abandoned（主0/备3）、Gollum, Riddle Master（主3/备0）、Nighthowl Pursuer（主4/备0） | N14: 加入大量HOB新牌的小黑本周也有一个八强成绩。主牌满编了Desolation Prowler、Nighthowl Pursuer还有3张Gollum, Riddle Master，备牌还带了Gollum the Abandoned | O14: Desolation Prowler | P14: Nighthowl Pursuer | Q14: Gollum, Riddle Master | R14: Gollum the Abandoned | S14: This Mono-Black Aggro list packed with HOB cards also made a Top 8 this week. The maindeck ran four each of Desolation Prowler and Nighthowl Pursuer, plus three Gollum, Riddle Master, with Gollum the Abandoned in the sideboard. | T14: This Mono-Black Aggro list packed with HOB cards also made a Top 8 this week. The maindeck ran four each of Desolation Prowler and Nighthowl Pursuer, plus three Gollum, Riddle Master, with Gollum the Abandoned in the sideboard. | U14: 4 × Corpses of the Lost; 2 × Dark Knight's Greatsword; 4 × Desolation Prowler; 4 × Dissection Practice; 4 × Forsaken Miner; 3 × Gollum, Riddle Master; 4 × Iridescent Vinelasher; 4 × Nighthowl Pursuer; 2 × Realm of Koh; 4 × Shoot the Sheriff; 3 × Soulstone Sanctuary; 4 × Sunset Saboteur; 18 × Swamp | V14: 3 × Deep-Cavern Bat; 4 × Duress; 3 × Elegy Acolyte; 2 × Ghost Vacuum; 3 × Gollum the Abandoned | W14: =IF(A14<>"KEEP","NOT SELECTED",IF(OR(D14="",N14="",COUNTA(O14:R14)<>4),"NEEDS INPUT",IF(OR(COUNTIF(O14:R14,O14)>1,COUNTIF(O14:R14,P14)>1,COUNTIF(O14:R14,Q14)>1,COUNTIF(O14:R14,R14)>1),"DUPLICATE CARDS",IF(OR(ISERROR(SEARCH("× "&O14&";",U14&"; "&V14&";")),ISERROR(SEARCH("× "&P14&";",U14&"; "&V14&";")),ISERROR(SEARCH("× "&Q14&";",U14&"; "&V14&";")),ISERROR(SEARCH("× "&R14&";",U14&"; "&V14&";"))),"CARD NOT IN DECK","READY")))) -> READY | X14: =IF(A14<>"KEEP","NOT SELECTED",IF(T14="","WAIT FOR ENGLISH STAGE","READY")) -> READY | Y14: mono-black-aggro | AA14: standard|mono-black-aggro|none
A15: DROP | B15: 2026-W34 | C15: standard | D15: new_technology | E15: Standard Challenge 32 · 12851725 | F15: 2026-08-18 | G15: 7 | H15: Mono-Red Aggro | I15: 纯红快攻 | J15: APPROVED | K15: Arkany1 | L15: deck:637e9fc345578cd3181a | M15: HOB 新卡：Smaug the Magnificent（主3/备0） | U15: 4 × Burst Lightning; 2 × Channeled Dragonfire; 4 × Emberheart Challenger; 4 × Greasewrench Goblin; 2 × Hexing Squelcher; 4 × Hired Claw; 20 × Mountain; 4 × Nova Hellkite; 4 × Shock; 3 × Smaug the Magnificent; 3 × Soulstone Sanctuary; 3 × Tersa Lightshatter; 3 × Zhao, the Moon Slayer | V15: 2 × Ghost Vacuum; 4 × Magebane Lizard; 4 × Scorching Shot; 2 × Soul-Guide Lantern; 3 × Sunspine Lynx | W15: =IF(A15<>"KEEP","NOT SELECTED",IF(OR(D15="",N15="",COUNTA(O15:R15)<>4),"NEEDS INPUT",IF(OR(COUNTIF(O15:R15,O15)>1,COUNTIF(O15:R15,P15)>1,COUNTIF(O15:R15,Q15)>1,COUNTIF(O15:R15,R15)>1),"DUPLICATE CARDS",IF(OR(ISERROR(SEARCH("× "&O15&";",U15&"; "&V15&";")),ISERROR(SEARCH("× "&P15&";",U15&"; "&V15&";")),ISERROR(SEARCH("× "&Q15&";",U15&"; "&V15&";")),ISERROR(SEARCH("× "&R15&";",U15&"; "&V15&";"))),"CARD NOT IN DECK","READY")))) -> NOT SELECTED | X15: =IF(A15<>"KEEP","NOT SELECTED",IF(T15="","WAIT FOR ENGLISH STAGE","READY")) -> NOT SELECTED | Y15: mono-red-aggro | AA15: standard|mono-red-aggro|none
A16: DROP | B16: 2026-W34 | C16: standard | D16: new_technology | E16: Standard Showcase Challenge · 12852807 | F16: 2026-08-22 | G16: 8 | H16: Selesnya Landfall | I16: 白绿地落 | J16: APPROVED | K16: joaoclaudioms | L16: deck:9e4997f4c6c8be5c7113 | M16: HOB 新卡：Warg Tactics（主0/备1） | U16: 3 × Ba Sing Se; 1 × Demolition Field; 4 × Earthbender Ascension; 4 × Erode; 3 × Escape Tunnel; 3 × Esper Origins; 4 × Fabled Passage; 9 × Forest; 4 × Icetill Explorer; 3 × Keen-Eyed Curator; 4 × Llanowar Elves; 1 × Lumbering Worldwagon; 4 × Mightform Harmonizer; 2 × Plains; 4 × Sazh's Chocobo; 3 × Shared Roots; 4 × Temple Garden | V16: 4 × Mossborn Hydra; 2 × Rest in Peace; 4 × Sapling Nursery; 2 × Sheltered by Ghosts; 2 × Spectacular Tactics; 1 × Warg Tactics | W16: =IF(A16<>"KEEP","NOT SELECTED",IF(OR(D16="",N16="",COUNTA(O16:R16)<>4),"NEEDS INPUT",IF(OR(COUNTIF(O16:R16,O16)>1,COUNTIF(O16:R16,P16)>1,COUNTIF(O16:R16,Q16)>1,COUNTIF(O16:R16,R16)>1),"DUPLICATE CARDS",IF(OR(ISERROR(SEARCH("× "&O16&";",U16&"; "&V16&";")),ISERROR(SEARCH("× "&P16&";",U16&"; "&V16&";")),ISERROR(SEARCH("× "&Q16&";",U16&"; "&V16&";")),ISERROR(SEARCH("× "&R16&";",U16&"; "&V16&";"))),"CARD NOT IN DECK","READY")))) -> NOT SELECTED | X16: =IF(A16<>"KEEP","NOT SELECTED",IF(T16="","WAIT FOR ENGLISH STAGE","READY")) -> NOT SELECTED | Y16: selesnya-landfall | AA16: standard|selesnya-landfall|none
A17: DROP | B17: 2026-W34 | C17: standard | D17: new_technology | E17: Standard Showcase Challenge · 12852807 | F17: 2026-08-22 | G17: 3 | H17: Dimir Midrange | I17: 蓝黑中速 | J17: APPROVED | K17: reojund | L17: deck:b8ef88fe784397622277 | M17: 构筑变化；deviation=22 | U17: 2 × Bitter Triumph; 4 × Enduring Curiosity; 4 × Floodpits Drowner; 2 × Fountainport; 4 × Gloomlake Verge; 3 × Hidden Lair; 4 × Island; 4 × Kaito, Bane of Nightmares; 2 × Lazav, Wearer of Faces; 1 × Requiting Hex; 2 × Restless Reef; 2 × Shoot the Sheriff; 1 × Spell Pierce; 1 × Spell Snare; 4 × Spyglass Siren; 4 × Swamp; 2 × The Wondrous Wasp; 2 × Tishana's Tidebinder; 3 × Tragic Trajectory; 2 × Wan Shi Tong, Librarian; 4 × Watery Grave; 3 × We Say Thee Nay! | V17: 1 × Annul; 3 × Duress; 3 × Faebloom Trick; 3 × Flashfreeze; 1 × Quantum Riddler; 1 × Requiting Hex; 1 × Spell Snare; 2 × Strategic Betrayal | W17: =IF(A17<>"KEEP","NOT SELECTED",IF(OR(D17="",N17="",COUNTA(O17:R17)<>4),"NEEDS INPUT",IF(OR(COUNTIF(O17:R17,O17)>1,COUNTIF(O17:R17,P17)>1,COUNTIF(O17:R17,Q17)>1,COUNTIF(O17:R17,R17)>1),"DUPLICATE CARDS",IF(OR(ISERROR(SEARCH("× "&O17&";",U17&"; "&V17&";")),ISERROR(SEARCH("× "&P17&";",U17&"; "&V17&";")),ISERROR(SEARCH("× "&Q17&";",U17&"; "&V17&";")),ISERROR(SEARCH("× "&R17&";",U17&"; "&V17&";"))),"CARD NOT IN DECK","READY")))) -> NOT SELECTED | X17: =IF(A17<>"KEEP","NOT SELECTED",IF(T17="","WAIT FOR ENGLISH STAGE","READY")) -> NOT SELECTED | Y17: dimir-midrange | AA17: standard|dimir-midrange|none
A18: DROP | B18: 2026-W34 | C18: standard | D18: new_technology | E18: Standard Challenge 32 · 12851694 | F18: 2026-08-17 | G18: 3 | H18: Selesnya Landfall | I18: 白绿地落 | J18: APPROVED | K18: Tree42o | L18: deck:7736e9df60779680ba40 | M18: 构筑变化；deviation=23 | U18: 3 × Ba Sing Se; 1 × Bristly Bill, Spine Sower; 2 × Dyadrine, Synthesis Amalgam; 4 × Earthbender Ascension; 4 × Erode; 3 × Escape Tunnel; 4 × Fabled Passage; 7 × Forest; 4 × Hushwood Verge; 4 × Icetill Explorer; 1 × Keen-Eyed Curator; 1 × Leatherhead, Swamp Stalker; 4 × Llanowar Elves; 4 × Mightform Harmonizer; 1 × Mossborn Hydra; 2 × Plains; 2 × Practiced Offense; 4 × Sazh's Chocobo; 2 × Snakeskin Veil; 1 × Surrak, Elusive Hunter; 2 × Temple Garden | V18: 1 × Leatherhead, Swamp Stalker; 2 × Mossborn Hydra; 2 × Requisition Raid; 2 × Rest in Peace; 3 × Sheltered by Ghosts; 1 × Surrak, Elusive Hunter; 2 × Torpor Orb; 2 × Voice of Victory | W18: =IF(A18<>"KEEP","NOT SELECTED",IF(OR(D18="",N18="",COUNTA(O18:R18)<>4),"NEEDS INPUT",IF(OR(COUNTIF(O18:R18,O18)>1,COUNTIF(O18:R18,P18)>1,COUNTIF(O18:R18,Q18)>1,COUNTIF(O18:R18,R18)>1),"DUPLICATE CARDS",IF(OR(ISERROR(SEARCH("× "&O18&";",U18&"; "&V18&";")),ISERROR(SEARCH("× "&P18&";",U18&"; "&V18&";")),ISERROR(SEARCH("× "&Q18&";",U18&"; "&V18&";")),ISERROR(SEARCH("× "&R18&";",U18&"; "&V18&";"))),"CARD NOT IN DECK","READY")))) -> NOT SELECTED | X18: =IF(A18<>"KEEP","NOT SELECTED",IF(T18="","WAIT FOR ENGLISH STAGE","READY")) -> NOT SELECTED | Y18: selesnya-landfall | AA18: standard|selesnya-landfall|none
A19: DROP | B19: 2026-W34 | C19: standard | D19: new_technology | E19: Standard Challenge 32 · 12851694 | F19: 2026-08-17 | G19: 4 | H19: Izzet Spellementals | I19: 红蓝元素 | J19: APPROVED | K19: HamAndCheese | L19: deck:b9b4d9e12138e46f4e1e | M19: 构筑变化；deviation=24 | U19: 4 × Burst Lightning; 4 × Eddymurk Crab; 2 × Get Out; 4 × Hearth Elemental; 8 × Island; 1 × Multiversal Passage; 4 × Opt; 3 × Prismari Charm; 4 × Riverpyre Verge; 4 × Sleight of Hand; 2 × Spell Pierce; 1 × Spell Snare; 4 × Spirebluff Canal; 4 × Steam Vents; 4 × Sunderflock; 4 × Traumatic Critique; 3 × Winternight Stories | V19: 1 × Annul; 1 × Belion, the Parched; 2 × Broadside Barrage; 4 × Colorstorm Stallion; 1 × Get Out; 1 × Impractical Joke; 2 × Soul-Guide Lantern; 1 × Spell Pierce; 1 × Spell Snare; 1 × The Legend of Kuruk | W19: =IF(A19<>"KEEP","NOT SELECTED",IF(OR(D19="",N19="",COUNTA(O19:R19)<>4),"NEEDS INPUT",IF(OR(COUNTIF(O19:R19,O19)>1,COUNTIF(O19:R19,P19)>1,COUNTIF(O19:R19,Q19)>1,COUNTIF(O19:R19,R19)>1),"DUPLICATE CARDS",IF(OR(ISERROR(SEARCH("× "&O19&";",U19&"; "&V19&";")),ISERROR(SEARCH("× "&P19&";",U19&"; "&V19&";")),ISERROR(SEARCH("× "&Q19&";",U19&"; "&V19&";")),ISERROR(SEARCH("× "&R19&";",U19&"; "&V19&";"))),"CARD NOT IN DECK","READY")))) -> NOT SELECTED | X19: =IF(A19<>"KEEP","NOT SELECTED",IF(T19="","WAIT FOR ENGLISH STAGE","READY")) -> NOT SELECTED | Y19: izzet-spellementals | AA19: standard|izzet-spellementals|none
A20: DROP | B20: 2026-W34 | C20: standard | D20: new_technology | E20: Standard Challenge 32 · 12851725 | F20: 2026-08-18 | G20: 5 | H20: 4-Color Tablet | I20: 四色石板 | J20: APPROVED | K20: Homaar | L20: deck:248ff5d358ec4e2c5910 | M20: 构筑变化；deviation=30 | U20: 3 × Bleachbone Verge; 4 × Blood Crypt; 3 × Consult the Star Charts; 2 × Deadly Cover-Up; 1 × Duress; 3 × Firebending Lesson; 2 × Flashback; 4 × Great Hall of the Biblioplex; 3 × Inevitable Defeat; 1 × Island; 4 × Jeskai Revelation; 1 × Nowhere to Run; 1 × Plains; 3 × Riverpyre Verge; 2 × Sacred Foundry; 3 × Sear; 2 × Shattered Sanctum; 2 × Shoot the Sheriff; 2 × Starting Town; 1 × Steam Vents; 4 × Stock Up; 1 × Swamp; 4 × Tablet of Discovery; 2 × Together as One; 1 × Undercity Sewers; 1 × Watery Grave | V20: 1 × Annul; 1 × Day of Black Sun; 1 × Disdainful Stroke; 3 × Duress; 1 × Fire Magic; 2 × Flashfreeze; 1 × Petrified Hamlet; 1 × Return the Favor; 1 × Riverchurn Monument; 2 × Sage of the Skies; 1 × Thor, God of Thunder | W20: =IF(A20<>"KEEP","NOT SELECTED",IF(OR(D20="",N20="",COUNTA(O20:R20)<>4),"NEEDS INPUT",IF(OR(COUNTIF(O20:R20,O20)>1,COUNTIF(O20:R20,P20)>1,COUNTIF(O20:R20,Q20)>1,COUNTIF(O20:R20,R20)>1),"DUPLICATE CARDS",IF(OR(ISERROR(SEARCH("× "&O20&";",U20&"; "&V20&";")),ISERROR(SEARCH("× "&P20&";",U20&"; "&V20&";")),ISERROR(SEARCH("× "&Q20&";",U20&"; "&V20&";")),ISERROR(SEARCH("× "&R20&";",U20&"; "&V20&";"))),"CARD NOT IN DECK","READY")))) -> NOT SELECTED | X20: =IF(A20<>"KEEP","NOT SELECTED",IF(T20="","WAIT FOR ENGLISH STAGE","READY")) -> NOT SELECTED | Y20: 4-color-tablet | AA20: standard|4-color-tablet|none
A21: DROP | B21: 2026-W34 | C21: standard | D21: new_technology | E21: Standard Challenge 32 · 12851694 | F21: 2026-08-17 | G21: 8 | H21: Mono-Red Aggro | I21: 纯红快攻 | J21: APPROVED | K21: Boin | L21: deck:d935d7cdcaf7bd41ca0a | M21: 构筑变化；deviation=21 | U21: 4 × Burst Lightning; 4 × Emberheart Challenger; 4 × Greasewrench Goblin; 3 × Hexing Squelcher; 4 × Hired Claw; 2 × Kellan, Planar Trailblazer; 3 × Lightning Strike; 20 × Mountain; 4 × Shock; 3 × Soulstone Sanctuary; 4 × Sunspine Lynx; 3 × Tersa Lightshatter; 2 × Zhao, the Moon Slayer | V21: 2 × Ghost Vacuum; 2 × Maelstrom Artisan; 4 × Magebane Lizard; 2 × Scorching Shot; 3 × Slagstorm; 2 × The Legend of Roku | W21: =IF(A21<>"KEEP","NOT SELECTED",IF(OR(D21="",N21="",COUNTA(O21:R21)<>4),"NEEDS INPUT",IF(OR(COUNTIF(O21:R21,O21)>1,COUNTIF(O21:R21,P21)>1,COUNTIF(O21:R21,Q21)>1,COUNTIF(O21:R21,R21)>1),"DUPLICATE CARDS",IF(OR(ISERROR(SEARCH("× "&O21&";",U21&"; "&V21&";")),ISERROR(SEARCH("× "&P21&";",U21&"; "&V21&";")),ISERROR(SEARCH("× "&Q21&";",U21&"; "&V21&";")),ISERROR(SEARCH("× "&R21&";",U21&"; "&V21&";"))),"CARD NOT IN DECK","READY")))) -> NOT SELECTED | X21: =IF(A21<>"KEEP","NOT SELECTED",IF(T21="","WAIT FOR ENGLISH STAGE","READY")) -> NOT SELECTED | Y21: mono-red-aggro | AA21: standard|mono-red-aggro|none
A22: KEEP | B22: 2026-W34 | C22: modern | D22: new_deck | E22: Modern Challenge 64 · 12852747 | F22: 2026-08-23 | G22: 8 | H22: Dimir Erayo | I22: 蓝黑伟代 | J22: APPROVED | K22: WaffleWiz | L22: deck:acc94e69d84da4b303d1 | M22: 新 Archetype；HOB 新卡：Bilbo, Thief in the Night（主3/备0）、Key to the Side-Door（主3/备0） | N22: HOB带来Bilbo和Key to the Side-Door之后，aspiringspike率先尝试了纯蓝版本的伟代套牌，不过本周没有八强成绩，只有两个高分。而这个版本是加入了Basim和更多黑色互动，本周取得一个八强。包括MSH补的Loki在内，新组件确实都非常适合这个思路。 | O22: Bilbo, Thief in the Night | P22: Key to the Side-Door | Q22: Basim Ibn Ishaq | R22: Erayo, Soratami Ascendant | S22: After HOB introduced Bilbo and Key to the Side-Door, aspiringspike was first to try a mono-blue Erayo build. It missed the Top 8 this week but posted two high-score finishes. This version added Basim and more black interaction and did reach a Top 8. The new pieces—including Loki from MSH—are all excellent fits for the strategy. | T22: After HOB introduced Bilbo and Key to the Side-Door, aspiringspike was first to try a mono-blue Erayo build. It missed the Top 8 this week but posted two high-score finishes. This version added Basim and more black interaction and did reach a Top 8. The new pieces—including Loki from MSH—are all excellent fits for the strategy. | U22: 1 × Aether Spellbomb; 3 × Basim Ibn Ishaq; 3 × Bilbo, Thief in the Night; 4 × Emry, Lurker of the Loch; 3 × Erayo, Soratami Ascendant; 4 × Fatal Push; 2 × Island; 3 × Key to the Side-Door; 3 × Metallic Rebuke; 4 × Mishra's Bauble; 4 × Mox Amber; 4 × Mox Opal; 1 × Nihil Spellbomb; 2 × Otawara, Soaring City; 3 × Polluted Delta; 1 × Sink into Stupor; 1 × Skateboard; 4 × Tamiyo, Inquisitive Student; 1 × Thoughtseize; 1 × Undercity Sewers; 4 × Urza's Saga; 4 × Watery Grave | V22: 3 × Consign to Memory; 2 × Force of Negation; 2 × Harbinger of the Seas; 2 × Kaito, Bane of Nightmares; 1 × Pithing Needle; 2 × Thoughtseize; 2 × Toxic Deluge; 1 × Vexing Bauble | W22: =IF(A22<>"KEEP","NOT SELECTED",IF(OR(D22="",N22="",COUNTA(O22:R22)<>4),"NEEDS INPUT",IF(OR(COUNTIF(O22:R22,O22)>1,COUNTIF(O22:R22,P22)>1,COUNTIF(O22:R22,Q22)>1,COUNTIF(O22:R22,R22)>1),"DUPLICATE CARDS",IF(OR(ISERROR(SEARCH("× "&O22&";",U22&"; "&V22&";")),ISERROR(SEARCH("× "&P22&";",U22&"; "&V22&";")),ISERROR(SEARCH("× "&Q22&";",U22&"; "&V22&";")),ISERROR(SEARCH("× "&R22&";",U22&"; "&V22&";"))),"CARD NOT IN DECK","READY")))) -> READY | X22: =IF(A22<>"KEEP","NOT SELECTED",IF(T22="","WAIT FOR ENGLISH STAGE","READY")) -> READY | Y22: erayo | AA22: modern|erayo|none
A23: KEEP | B23: 2026-W34 | C23: modern | D23: new_deck | E23: Modern Challenge 96 · 12851716 | F23: 2026-08-19 | G23: 3 | H23: Jeskai Ponza | I23: 洁斯凯炸地 | J23: APPROVED | K23: stefansson30952 | L23: deck:78a27b72522b16549da7 | M23: 新 Archetype | N23: 红白炸地的基底，混入蓝色加入Quantum Riddler续航，还有Mana Leak作为许可咒语，让套牌可以应对的局面更丰富。不过个人对这个法术力基础是否能支持三色还是有一定疑虑。 | O23: Mana Leak | P23: Quantum Riddler | Q23: Price of Freedom | R23: Field of Ruin | S23: Built on the Boros Ponza shell, this version splashes blue for Quantum Riddler as card advantage and Mana Leak as permission, expanding the range of situations it can answer. I still have some doubts about whether the mana base can reliably support all three colors. | T23: Built on the Boros Ponza shell, this version splashes blue for Quantum Riddler as card advantage and Mana Leak as permission, expanding the range of situations it can answer. I still have some doubts about whether the mana base can reliably support all three colors. | U23: 2 × Avengers Disassembled; 1 × Castle Ardenvale; 3 × Cleansing Wildfire; 3 × Cori Mountain Monastery; 4 × Demolition Field; 4 × Erode; 4 × Field of Ruin; 3 × Flooded Strand; 4 × Galvanic Discharge; 1 × Hallowed Fountain; 1 × Island; 4 × Mana Leak; 1 × Mountain; 4 × Path to Exile; 4 × Plains; 4 × Price of Freedom; 3 × Quantum Riddler; 1 × Raugrin Triome; 1 × Sacred Foundry; 4 × Solitude; 1 × Steam Vents; 3 × Wrath of the Skies | V23: 2 × Avengers Disassembled; 1 × Dovin's Veto; 1 × Faerie Macabre; 4 × High Noon; 1 × Rest in Peace; 1 × Surgical Extraction; 1 × Vexing Bauble; 2 × Wear/Tear; 1 × Wrath of God; 1 × Wrath of the Skies | W23: =IF(A23<>"KEEP","NOT SELECTED",IF(OR(D23="",N23="",COUNTA(O23:R23)<>4),"NEEDS INPUT",IF(OR(COUNTIF(O23:R23,O23)>1,COUNTIF(O23:R23,P23)>1,COUNTIF(O23:R23,Q23)>1,COUNTIF(O23:R23,R23)>1),"DUPLICATE CARDS",IF(OR(ISERROR(SEARCH("× "&O23&";",U23&"; "&V23&";")),ISERROR(SEARCH("× "&P23&";",U23&"; "&V23&";")),ISERROR(SEARCH("× "&Q23&";",U23&"; "&V23&";")),ISERROR(SEARCH("× "&R23&";",U23&"; "&V23&";"))),"CARD NOT IN DECK","READY")))) -> READY | X23: =IF(A23<>"KEEP","NOT SELECTED",IF(T23="","WAIT FOR ENGLISH STAGE","READY")) -> READY | Y23: jeskai-ponza | AA23: modern|jeskai-ponza|none
A24: DROP | B24: 2026-W34 | C24: modern | D24: new_technology | E24: Modern Challenge 64 · 12852736 | F24: 2026-08-22 | G24: 1 | H24: Esper Blink | I24: 艾斯波云移 | J24: APPROVED | K24: Willthepill | L24: deck:b2abf5fdb96d22201849 | M24: 高胜占比 3.9% → 9.1%（+5.16pp） | U24: 1 × Boggart Trawler; 1 × Consign to Memory; 3 × Emperor of Bones; 2 × Ephemerate; 4 × Fatal Push; 3 × Flickerwisp; 4 × Flooded Strand; 2 × Godless Shrine; 1 × Hallowed Fountain; 4 × Marsh Flats; 1 × Meticulous Archive; 4 × Overlord of the Balemurk; 4 × Phelia, Exuberant Shepherd; 2 × Plains; 1 × Polluted Delta; 1 × Prismatic Ending; 4 × Quantum Riddler; 1 × Shadowy Backstreet; 4 × Solitude; 1 × Swamp; 2 × Teferi, Time Raveler; 4 × Thoughtseize; 1 × Undercity Sewers; 1 × Watery Grave; 4 × Witch Enchanter | V24: 2 × Clarion Conqueror; 3 × Consign to Memory; 2 × Containment Priest; 2 × Damping Sphere; 2 × High Noon; 1 × White Orchid Phantom; 3 × Wrath of the Skies | W24: =IF(A24<>"KEEP","NOT SELECTED",IF(OR(D24="",N24="",COUNTA(O24:R24)<>4),"NEEDS INPUT",IF(OR(COUNTIF(O24:R24,O24)>1,COUNTIF(O24:R24,P24)>1,COUNTIF(O24:R24,Q24)>1,COUNTIF(O24:R24,R24)>1),"DUPLICATE CARDS",IF(OR(ISERROR(SEARCH("× "&O24&";",U24&"; "&V24&";")),ISERROR(SEARCH("× "&P24&";",U24&"; "&V24&";")),ISERROR(SEARCH("× "&Q24&";",U24&"; "&V24&";")),ISERROR(SEARCH("× "&R24&";",U24&"; "&V24&";"))),"CARD NOT IN DECK","READY")))) -> NOT SELECTED | X24: =IF(A24<>"KEEP","NOT SELECTED",IF(T24="","WAIT FOR ENGLISH STAGE","READY")) -> NOT SELECTED | Y24: esper-blink | AA24: modern|esper-blink|none
A25: KEEP | B25: 2026-W34 | C25: modern | D25: new_technology | E25: Modern Challenge 32 · 12851707 | F25: 2026-08-19 | G25: 1 | H25: Izzet Steel-Cutter | I25: 红蓝介刀 | J25: APPROVED | K25: mechrataal | L25: deck:29ffa26abbc811f769a1 | M25: HOB 新卡：Bilbo, Thief in the Night（主4/备0）、Key to the Side-Door（主1/备0） | N25: 传统介刀套牌中，也开始有加入Bilbo的版本出成绩，本周一套满编并带了一张Key to the Side-Door的版本拿下一个八强。 | O25: Bilbo, Thief in the Night | P25: Key to the Side-Door | Q25: Loki, God of Mischief | R25: Cori-Steel Cutter | S25: Traditional Steel-Cutter shells are also starting to post results with Bilbo. This week, a list with the full four copies and one Key to the Side-Door made a Top 8. | T25: Traditional Steel-Cutter shells are also starting to post results with Bilbo. This week, a list with the full four copies and one Key to the Side-Door made a Top 8. | U25: 1 × Aether Spellbomb; 4 × Bilbo, Thief in the Night; 1 × Breeding Pool; 4 × Cori-Steel Cutter; 4 × Emry, Lurker of the Loch; 1 × Island; 1 × Key to the Side-Door; 4 × Loki, God of Mischief; 2 × Metallic Rebuke; 1 × Minamo, School at Water's Edge; 4 × Mishra's Bauble; 1 × Mountain; 3 × Mox Amber; 4 × Mox Opal; 1 × Otawara, Soaring City; 1 × Pyrite Spellbomb; 4 × Scalding Tarn; 2 × Sink into Stupor; 1 × Skateboard; 1 × Soul-Guide Lantern; 3 × Steam Vents; 4 × Tamiyo, Inquisitive Student; 4 × Unholy Heat; 4 × Urza's Saga | V25: 2 × Consign to Memory; 2 × Flame of Anor; 2 × Force of Negation; 2 × Harbinger of the Seas; 2 × Haywire Mite; 2 × Metallic Rebuke; 1 × Pithing Needle; 1 × Soul-Guide Lantern; 1 × Vexing Bauble | W25: =IF(A25<>"KEEP","NOT SELECTED",IF(OR(D25="",N25="",COUNTA(O25:R25)<>4),"NEEDS INPUT",IF(OR(COUNTIF(O25:R25,O25)>1,COUNTIF(O25:R25,P25)>1,COUNTIF(O25:R25,Q25)>1,COUNTIF(O25:R25,R25)>1),"DUPLICATE CARDS",IF(OR(ISERROR(SEARCH("× "&O25&";",U25&"; "&V25&";")),ISERROR(SEARCH("× "&P25&";",U25&"; "&V25&";")),ISERROR(SEARCH("× "&Q25&";",U25&"; "&V25&";")),ISERROR(SEARCH("× "&R25&";",U25&"; "&V25&";"))),"CARD NOT IN DECK","READY")))) -> READY | X25: =IF(A25<>"KEEP","NOT SELECTED",IF(T25="","WAIT FOR ENGLISH STAGE","READY")) -> READY | Y25: steel-cutter | Z25: izzet | AA25: modern|steel-cutter|izzet
